Workbook

Sheet Resultats Reals
A1: Grup | B1: Posició | C1: Equip | E1: Setzens | F1: Vuitens | G1: Quarts | H1: Semis | I1: Finalistes | J1: Campió | K1: MVP | L1: Resultat Final | N1: Jugador Pichichi | O1: Gols
A2: Grup A | B2: 1r | C2: Mèxic | E2: =+C2 -> Mèxic | F2: Canadà | G2: Marroc | H2: França | I2: Pendent | J2: Pendent | K2: Pendent | L2: Pendent | N2: Lionel Messi | O2: 8
A3: Grup A | B3: 2n | C3: Sud-àfrica | E3: =+C3 -> Sud-àfrica | F3: Brasil | G3: França | H3: Espanya | I3: Pendent | N3: Kylian Mbappé | O3: 8
A4: Grup A | B4: 3r | C4: Corea del Sud | E4: =+C5 -> Suïssa | F4: Marroc | G4: Noruega | H4: Anglaterra | N4: Erling Haaland | O4: 7
A5: Grup B | B5: 1r | C5: Suïssa | E5: =+C6 -> Canadà | F5: Paraguai | G5: Anglaterra | H5: Argentina | N5: Harry Kane | O5: 6
A6: Grup B | B6: 2n | C6: Canadà | E6: =+C8 -> Brasil | F6: Noruega | G6: Bèlgica | N6: Vinícius Júnior | O6: 4
A7: Grup B | B7: 3r | C7: Bòsnia i Hercegovina | E7: =+C9 -> Marroc | F7: França | G7: Espanya | N7: Mikel Oyarzabal | O7: 4
A8: Grup C | B8: 1r | C8: Brasil | E8: =+C11 -> Estats Units | F8: Mèxic | G8: Suïssa | N8: Lamine Yamal | O8: 1
A9: Grup C | B9: 2n | C9: Marroc | E9: =+C12 -> Austràlia | F9: Anglaterra | G9: Argentina | N9: Endrick | O9: 0
A10: Grup C | B10: 3r | C10: Escòcia | E10: =+C14 -> Alemanya | F10: Estats Units | N10: Ferran Torres | O10: 0
A11: Grup D | B11: 1r | C11: Estats Units | E11: =+C15 -> Costa d'Ivori | F11: Bèlgica | N11: Julián Álvarez | O11: 1
A12: Grup D | B12: 2n | C12: Austràlia | E12: =+C17 -> Països Baixos | F12: Suïssa | N12: Nico Williams | O12: 0
A13: Grup D | B13: 3r | C13: Paraguai | E13: =+C18 -> Japó | F13: Espanya | N13: Rodri | O13: 0
A14: Grup E | B14: 1r | C14: Alemanya | E14: =+C20 -> Bèlgica | F14: Portugal | N14: Sørloth | O14: 0
A15: Grup E | B15: 2n | C15: Costa d'Ivori | E15: =+C21 -> Egipte | F15: Egipte
A16: Grup E | B16: 3r | C16: Equador | E16: =+C23 -> Espanya | F16: Argentina
A17: Grup F | B17: 1r | C17: Països Baixos | E17: =+C24 -> Cap Verd | F17: Colòmbia
A18: Grup F | B18: 2n | C18: Japó | E18: =+C26 -> França
A19: Grup F | B19: 3r | C19: Suècia | E19: =+C27 -> Noruega
A20: Grup G | B20: 1r | C20: Bèlgica | E20: =+C29 -> Argentina
A21: Grup G | B21: 2n | C21: Egipte | E21: =+C30 -> Àustria
A22: Grup G | B22: 3r | C22: Iran | E22: =+C32 -> Colòmbia
A23: Grup H | B23: 1r | C23: Espanya | E23: =+C33 -> Portugal
A24: Grup H | B24: 2n | C24: Cap Verd | E24: =+C35 -> Anglaterra
A25: Grup H | B25: 3r | C25: Uruguai | E25: =+C36 -> Croàcia
A26: Grup I | B26: 1r | C26: França | E26: RD Congo
A27: Grup I | B27: 2n | C27: Noruega | E27: Suècia
A28: Grup I | B28: 3r | C28: Senegal | E28: Ghana
A29: Grup J | B29: 1r | C29: Argentina | E29: Equador
A30: Grup J | B30: 2n | C30: Àustria | E30: Bòsnia i Hercegovina
A31: Grup J | B31: 3r | C31: Algèria | E31: Paraguai
A32: Grup K | B32: 1r | C32: Colòmbia | E32: Algèria
A33: Grup K | B33: 2n | C33: Portugal | E33: Senegal
A34: Grup K | B34: 3r | C34: RD Congo
A35: Grup L | B35: 1r | C35: Anglaterra
A36: Grup L | B36: 2n | C36: Croàcia
A37: Grup L | B37: 3r | C37: Ghana

Sheet Calendari
A1: Fase | B1: Partit | C1: Data | D1: Hora | E1: Resultat
A2: Setzens de final | B2: Sud-àfrica vs Canadà | C2: 46201 | D2: Finalitzat | E2: 0-1
A3: Setzens de final | B3: Brasil vs Japó | C3: 46202 | D3: Finalitzat | E3: 2-1
A4: Setzens de final | B4: Alemanya vs Paraguai | C4: 46202 | D4: Finalitzat | E4: 1(3)-1(4)
A5: Setzens de final | B5: Països Baixos vs Marroc | C5: 46203 | D5: Finalitzat | E5: 1(2)-1(3)
A6: Setzens de final | B6: Costa d'Ivori vs Noruega | C6: 46203 | D6: Finalitzat | E6: 1-2
A7: Setzens de final | B7: França vs Suècia | C7: 46203 | D7: Finalitzat | E7: 3-0
A8: Setzens de final | B8: Mèxic vs Equador | C8: 46204 | D8: Finalitzat | E8: 2-0
A9: Setzens de final | B9: Anglaterra vs RD Congo | C9: 46204 | D9: Finalitzat | E9: 2-1
A10: Setzens de final | B10: Bèlgica vs Senegal | C10: 46204 | D10: Finalitzat | E10: 3-2
A11: Setzens de final | B11: Estats Units vs Bòsnia i Hercegovina | C11: 46205 | D11: Finalitzat | E11: 2-0
A12: Setzens de final | B12: Espanya vs Àustria | C12: 46205 | D12: Finalitzat | E12: 3-0
A13: Setzens de final | B13: Portugal vs Croàcia | C13: 46206 | D13: Finalitzat | E13: 2-1
... A33: Final | B33: Pendent rivals | C33: 46222 | D33: 21:00h | E33: Pendent

Sheet Porra
A1: Participants | B1: Departament | C1: Grup A 1r | D1: Grup B 1r | E1: Grup C 1r | F1: Grup D 1r | G1: Grup E 1r | H1: Grup F 1r | I1: Grup G 1r | J1: Grup H 1r | K1: Grup I 1r | L1: Grup J 1r | M1: Grup K 1r | N1: Grup L 1r | O1: Grup A 2n | P1: Grup B 2n | Q1: Grup C 2n | R1: Grup D 2n | S1: Grup E 2n | T1: Grup F 2n | U1: Grup G 2n | V1: Grup H 2n | W1: Grup I 2n | X1: Grup J 2n | Y1: Grup K 2n | Z1: Grup L 2n | AA1: Grup A 3r | AB1: Grup B 3r | AC1: Grup C 3r | AD1: Grup D 3r | AE1: Grup E 3r | AF1: Grup F 3r | AG1: Grup G 3r | AH1: Grup H 3r | AI1: Grup I 3r | AJ1: Grup J 3r | AK1: Grup K 3r | AL1: Grup L 3r | AM1: Vuitens_1 | AN1: Vuitens_2 | AO1: Vuitens_3 | AP1: Vuitens_4 | AQ1: Vuitens_5 | AR1: Vuitens_6 | AS1: Vuitens_7 | AT1: Vuitens_8 | AU1: Vuitens_9 | AV1: Vuitens_10 | AW1: Vuitens_11 | AX1: Vuitens_12 | AY1: Vuitens_13 | AZ1: Vuitens_14 | BA1: Vuitens_15 | BB1: Vuitens_16 | BC1: Quarts_1 | BD1: Quarts_2 | BE1: Quarts_3 | BF1: Quarts_4 | BG1: Quarts_5 | BH1: Quarts_6 | BI1: Quarts_7 | BJ1: Quarts_8 | BK1: Semis_1 | BL1: Semis_2 | BM1: Semis_3 | BN1: Semis_4 | BO1: Final_1 | BP1: Final_2 | BQ1: Campió | BR1: Resultat final | BS1: MVP | BT1: Pichichi | BU1: Punts Grups 1r | BV1: Punts Grups 2n | BW1: Punts Grups 3r | BX1: Punts Vuitens | BY1: Punts Quarts | BZ1: Punts Semis | CA1: Punts Finalistes | CB1: Punts Campió | CC1: Punts MVP | CD1: Punts Pichichi | CE1: Resultat Final | CF1: Total Punts
A2: Rhandy Sosa | B2: Manteniment | C2: Mèxic | D2: Suïssa | E2: Brasil | F2: Estats Units | G2: Alemanya | H2: Països Baixos | I2: Bèlgica | J2: Espanya | K2: França | L2: Argentina | M2: Portugal | N2: Anglaterra | O2: Corea del Sud | P2: Canadà | Q2: Marroc | R2: Turquia | S2: Equador | T2: Japó | U2: Iran | V2: Uruguai | W2: Noruega | X2: Àustria | Y2: Colòmbia | Z2: Croàcia | AA2: República Txeca | AB2: Bòsnia i Hercegovina | AC2: Escòcia | AD2: Paraguai | AE2: Costa d'Ivori | AF2: Suècia | AG2: Egipte | AH2: Cap Verd | AI2: Senegal | AJ2: Algèria | AK2: Uzbekistan | AL2: Ghana | AM2: Alemanya | AN2: França | AO2: Corea del Sud | AP2: Països Baixos | AQ2: Colòmbia | AR2: Espanya | AS2: Estats Units | AT2: Bèlgica | AU2: Brasil | AV2: Equador | AW2: Mèxic | AX2: Anglaterra | AY2: Argentina | AZ2: Turquia | BA2: Suïssa | BB2: Portugal | BC2: França | BD2: Països Baixos | BE2: Espanya | BF2: Bèlgica | BG2: Brasil | BH2: Anglaterra | BI2: Argentina | BJ2: Portugal | BK2: França | BL2: Espanya | BM2: Brasil | BN2: Argentina | BO2: França | BP2: Argentina | BQ2: Argentina | BS2: Lionel Messi | BT2: Kylian Mbappé | BU2: =IF(C2='Resultats Reals'!$C$2,2,IF(OR(C2='Resultats Reals'!$C$3,COUNTIF('Resultats Reals'!$E$2:$E$33,C2)>0),1,0))+IF(D2='Resultats Reals'!$C$5,2,IF(OR(D2='Resultats Reals'!$C$6,COUNTIF('Resultats Reals'!$E$2:$E$33,D2)>0),1,0))+IF(E2='Resultats Reals'!$C$8,2,IF(OR(E2='Resultats Reals'!$C$9,COUNTIF('Resultats Reals'!$E$2:$E$33,E2)>0),1,0))+IF(F2='Resultats Reals'!$C$11,2,IF(OR(F2='Resultats Reals'!$C$12,COUNTIF('Resultats Reals'!$E$2:$E$33,F2)>0),1,0))+IF(G2='Resultats Reals'!$C$14,2,IF(OR(G2='Resultats Reals'!$C$15,COUNTIF('Resultats Reals'!$E$2:$E$33,G2)>0),1,0))+IF(H2='Resultats Reals'!$C$17,2,IF(OR(H2='Resultats Reals'!$C$18,COUNTIF('Resultats Reals'!$E$2:$E$33,H2)>0),1,0))+IF(I2='Resultats Reals'!$C$20,2,IF(OR(I2='Resultats Reals'!$C$21,COUNTIF('Resultats Reals'!$E$2:$E$33,I2)>0),1,0))+IF(J2='Resultats Reals'!$C$23,2,IF(OR(J2='Resultats Reals'!$C$24,COUNTIF('Resultats Reals'!$E$2:$E$33,J2)>0),1,0))+IF(K2='Resultats Reals'!$C$26,2,IF(OR(K2='Resultats Reals'!$C$27,COUNTIF('Resultats Reals'!$E$2:$E$33,K2)>0),1,0))+IF(L2='Resultats Reals'!$C$29,2,IF(OR(L2='Resultats Reals'!$C$30,COUNTIF('Resultats Reals'!$E$2:$E$33,L2)>0),1,0))+IF(M2='Resultats Reals'!$C$32,2,IF(OR(M2='Resultats Reals'!$C$33,COUNTIF('Resultats Reals'!$E$2:$E$33,M2)>0),1,0))+IF(N2='Resultats Reals'!$C$35,2,IF(OR(N2='Resultats Reals'!$C$36,COUNTIF('Resultats Reals'!$E$2:$E$33,N2)>0),1,0)) -> 23 | BV2: =IF(O2='Resultats Reals'!$C$3,2,IF(OR(O2='Resultats Reals'!$C$2,COUNTIF('Resultats Reals'!$E$2:$E$33,O2)>0),1,0))+IF(P2='Resultats Reals'!$C$6,2,IF(OR(P2='Resultats Reals'!$C$5,COUNTIF('Resultats Reals'!$E$2:$E$33,P2)>0),1,0))+IF(Q2='Resultats Reals'!$C$9,2,IF(OR(Q2='Resultats Reals'!$C$8,COUNTIF('Resultats Reals'!$E$2:$E$33,Q2)>0),1,0))+IF(R2='Resultats Reals'!$C$12,2,IF(OR(R2='Resultats Reals'!$C$11,COUNTIF('Resultats Reals'!$E$2:$E$33,R2)>0),1,0))+IF(S2='Resultats Reals'!$C$15,2,IF(OR(S2='Resultats Reals'!$C$14,COUNTIF('Resultats Reals'!$E$2:$E$33,S2)>0),1,0))+IF(T2='Resultats Reals'!$C$18,2,IF(OR(T2='Resultats Reals'!$C$17,COUNTIF('Resultats Reals'!$E$2:$E$33,T2)>0),1,0))+IF(U2='Resultats Reals'!$C$21,2,IF(OR(U2='Resultats Reals'!$C$20,COUNTIF('Resultats Reals'!$E$2:$E$33,U2)>0),1,0))+IF(V2='Resultats Reals'!$C$24,2,IF(OR(V2='Resultats Reals'!$C$23,COUNTIF('Resultats Reals'!$E$2:$E$33,V2)>0),1,0))+IF(W2='Resultats Reals'!$C$27,2,IF(OR(W2='Resultats Reals'!$C$26,COUNTIF('Resultats Reals'!$E$2:$E$33,W2)>0),1,0))+IF(X2='Resultats Reals'!$C$30,2,IF(OR(X2='Resultats Reals'!$C$29,COUNTIF('Resultats Reals'!$E$2:$E$33,X2)>0),1,0))+IF(Y2='Resultats Reals'!$C$33,2,IF(OR(Y2='Resultats Reals'!$C$32,COUNTIF('Resultats Reals'!$E$2:$E$33,Y2)>0),1,0))+IF(Z2='Resultats Reals'!$C$36,2,IF(OR(Z2='Resultats Reals'!$C$35,COUNTIF('Resultats Reals'!$E$2:$E$33,Z2)>0),1,0)) -> 14 | BW2: =IF(AA2='Resultats Reals'!$C$4,IF(COUNTIF('Resultats Reals'!$E$2:$E$33,AA2)>0,2,0.5),IF(OR(AA2='Resultats Reals'!$C$2,AA2='Resultats Reals'!$C$3,COUNTIF('Resultats Reals'!$E$2:$E$33,AA2)>0),1,0))+IF(AB2='Resultats Reals'!$C$7,IF(COUNTIF('Resultats Reals'!$E$2:$E$33,AB2)>0,2,0.5),IF(OR(AB2='Resultats Reals'!$C$5,AB2='Resultats Reals'!$C$6,COUNTIF('Resultats Reals'!$E$2:$E$33,AB2)>0),1,0))+IF(AC2='Resultats Reals'!$C$10,IF(COUNTIF('Resultats Reals'!$E$2:$E$33,AC2)>0,2,0.5),IF(OR(AC2='Resultats Reals'!$C$8,AC2='Resultats Reals'!$C$9,COUNTIF('Resultats Reals'!$E$2:$E$33,AC2)>0),1,0))+IF(AD2='Resultats Reals'!$C$13,IF(COUNTIF('Resultats Reals'!$E$2:$E$33,AD2)>0,2,0.5),IF(OR(AD2='Resultats Reals'!$C$11,AD2='Resultats Reals'!$C$12,COUNTIF('Resultats Reals'!$E$2:$E$33,AD2)>0),1,0))+IF(AE2='Resultats Reals'!$C$16,IF(COUNTIF('Resultats Reals'!$E$2:$E$33,AE2)>0,2,0.5),IF(OR(AE2='Resultats Reals'!$C$14,AE2='Resultats Reals'!$C$15,COUNTIF('Resultats Reals'!$E$2:$E$33,AE2)>0),1,0))+IF(AF2='Resultats Reals'!$C$19,IF(COUNTIF('Resultats Reals'!$E$2:$E$33,AF2)>0,2,0.5),IF(OR(AF2='Resultats Reals'!$C$17,AF2='Resultats Reals'!$C$18,COUNTIF('Resultats Reals'!$E$2:$E$33,AF2)>0),1,0))+IF(AG2='Resultats Reals'!$C$22,IF(COUNTIF('Resultats Reals'!$E$2:$E$33,AG2)>0,2,0.5),IF(OR(AG2='Resultats Reals'!$C$20,AG2='Resultats Reals'!$C$21,COUNTIF('Resultats Reals'!$E$2:$E$33,AG2)>0),1,0))+IF(AH2='Resultats Reals'!$C$25,IF(COUNTIF('Resultats Reals'!$E$2:$E$33,AH2)>0,2,0.5),IF(OR(AH2='Resultats Reals'!$C$23,AH2='Resultats Reals'!$C$24,COUNTIF('Resultats Reals'!$E$2:$E$33,AH2)>0),1,0))+IF(AI2='Resultats Reals'!$C$28,IF(COUNTIF('Resultats Reals'!$E$2:$E$33,AI2)>0,2,0.5),IF(OR(AI2='Resultats Reals'!$C$26,AI2='Resultats Reals'!$C$27,COUNTIF('Resultats Reals'!$E$2:$E$33,AI2)>0),1,0))+IF(AJ2='Resultats Reals'!$C$31,IF(COUNTIF('Resultats Reals'!$E$2:$E$33,AJ2)>0,2,0.5),IF(OR(AJ2='Resultats Reals'!$C$29,AJ2='Resultats Reals'!$C$30,COUNTIF('Resultats Reals'!$E$2:$E$33,AJ2)>0),1,0))+IF(AK2='Resultats Reals'!$C$34,IF(COUNTIF('Resultats Reals'!$E$2:$E$33,AK2)>0,2,0.5),IF(OR(AK2='Resultats Reals'!$C$32,AK2='Resultats Reals'!$C$33,COUNTIF('Resultats Reals'!$E$2:$E$33,AK2)>0),1,0))+IF(AL2='Resultats Reals'!$C$37,IF(COUNTIF('Resultats Reals'!$E$2:$E$33,AL2)>0,2,0.5),IF(OR(AL2='Resultats Reals'!$C$35,AL2='Resultats Reals'!$C$36,COUNTIF('Resultats Reals'!$E$2:$E$33,AL2)>0),1,0)) -> 15.5 | BX2: =IF(COUNTIF('Resultats Reals'!$F$2:$F$17,AM2)>0,1,0)+IF(COUNTIF('Resultats Reals'!$F$2:$F$17,AN2)>0,1,0)+IF(COUNTIF('Resultats Reals'!$F$2:$F$17,AO2)>0,1,0)+IF(COUNTIF('Resultats Reals'!$F$2:$F$17,AP2)>0,1,0)+IF(COUNTIF('Resultats Reals'!$F$2:$F$17,AQ2)>0,1,0)+IF(COUNTIF('Resultats Reals'!$F$2:$F$17,AR2)>0,1,0)+IF(COUNTIF('Resultats Reals'!$F$2:$F$17,AS2)>0,1,0)+IF(COUNTIF('Resultats Reals'!$F$2:$F$17,AT2)>0,1,0)+IF(COUNTIF('Resultats Reals'!$F$2:$F$17,AU2)>0,1,0)+IF(COUNTIF('Resultats Reals'!$F$2:$F$17,AV2)>0,1,0)+IF(COUNTIF('Resultats Reals'!$F$2:$F$17,AW2)>0,1,0)+IF(COUNTIF('Resultats Reals'!$F$2:$F$17,AX2)>0,1,0)+IF(COUNTIF('Resultats Reals'!$F$2:$F$17,AY2)>0,1,0)+IF(COUNTIF('Resultats Reals'!$F$2:$F$17,AZ2)>0,1,0)+IF(COUNTIF('Resultats Reals'!$F$2:$F$17,BA2)>0,1,0)+IF(COUNTIF('Resultats Reals'!$F$2:$F$17,BB2)>0,1,0) -> 11 | BY2: =IF(COUNTIF('Resultats Reals'!$G$2:$G$9,BC2)>0,1,0)+IF(COUNTIF('Resultats Reals'!$G$2:$G$9,BD2)>0,1,0)+IF(COUNTIF('Resultats Reals'!$G$2:$G$9,BE2)>0,1,0)+IF(COUNTIF('Resultats Reals'!$G$2:$G$9,BF2)>0,1,0)+IF(COUNTIF('Resultats Reals'!$G$2:$G$9,BG2)>0,1,0)+IF(COUNTIF('Resultats Reals'!$G$2:$G$9,BH2)>0,1,0)+IF(COUNTIF('Resultats Reals'!$G$2:$G$9,BI2)>0,1,0)+IF(COUNTIF('Resultats Reals'!$G$2:$G$9,BJ2)>0,1,0) -> 5 | BZ2: =IF(COUNTIF('Resultats Reals'!$H$2:$H$5,BK2)>0,1,0)+IF(COUNTIF('Resultats Reals'!$H$2:$H$5,BL2)>0,1,0)+IF(COUNTIF('Resultats Reals'!$H$2:$H$5,BM2)>0,1,0)+IF(COUNTIF('Resultats Reals'!$H$2:$H$5,BN2)>0,1,0) -> 3 | CA2: =IF(COUNTIF('Resultats Reals'!$I$2:$I$3,BO2)>0,3,0)+IF(COUNTIF('Resultats Reals'!$I$2:$I$3,BP2)>0,3,0) -> 0 | CB2: =IF(BQ2='Resultats Reals'!$J$2,5,0) -> 0 | CC2: =IF(BS2='Resultats Reals'!$K$2,5,0) -> 0 | CD2: =IFERROR(VLOOKUP(BT2,'Resultats Reals'!$N$2:$O$100,2,FALSE),0) -> 8 | CE2: =IF(BR2='Resultats Reals'!$L$2,5,0) -> 0 | CF2: =SUM(BU2:CE2) -> 79.5
A3: Marc Llopis | B3: Obres | C3: Mèxic | D3: Canadà | E3: Brasil | F3: Estats Units | G3: Alemanya | H3: Països Baixos | I3: Bèlgica | J3: Espanya | K3: França | L3: Argentina | M3: Portugal | N3: Anglaterra | O3: Corea del Sud | P3: Suïssa | Q3: Marroc | R3: Turquia | S3: Costa d'Ivori | T3: Japó | U3: Egipte | V3: Uruguai | W3: Noruega | X3: Àustria | Y3: Colòmbia | Z3: Croàcia | AA3: República Txeca | AB3: Qatar | AC3: Escòcia | AD3: Austràlia | AE3: Equador | AF3: Suècia | AG3: Iran | AH3: Aràbia Saudita | AI3: Senegal | AJ3: Algèria | AK3: Uzbekistan | AL3: Ghana | AM3: França | AN3: Argentina | AO3: Brasil | AP3: Anglaterra | AQ3: Espanya | AR3: Alemanya | AS3: Portugal | AT3: Països Baixos | AU3: Estats Units | AV3: Mèxic | AW3: Uruguai | AX3: Marroc | AY3: Croàcia | AZ3: Japó | BA3: Colòmbia | BB3: Suïssa | BC3: França | BD3: Argentina | BE3: Brasil | BF3: Anglaterra | BG3: Espanya | BH3: Alemanya | BI3: Portugal | BJ3: Països Baixos | BK3: França | BL3: Argentina | BM3: Espanya | BN3: Brasil | BO3: França | BP3: Espanya | BQ3: Espanya | BS3: Lamine Yamal | BT3: Kylian Mbappé | BU3: =IF(C3='Resultats Reals'!$C$2,2,IF(OR(C3='Resultats Reals'!$C$3,COUNTIF('Resultats Reals'!$E$2:$E$33,C3)>0),1,0))+IF(D3='Resultats Reals'!$C$5,2,IF(OR(D3='Resultats Reals'!$C$6,COUNTIF('Resultats Reals'!$E$2:$E$33,D3)>0),1,0))+IF(E3='Resultats Reals'!$C$8,2,IF(OR(E3='Resultats Reals'!$C$9,COUNTIF('Resultats Reals'!$E$2:$E$33,E3)>0),1,0))+IF(F3='Resultats Reals'!$C$11,2,IF(OR(F3='Resultats Reals'!$C$12,COUNTIF('Resultats Reals'!$E$2:$E$33,F3)>0),1,0))+IF(G3='Resultats Reals'!$C$14,2,IF(OR(G3='Resultats Reals'!$C$15,COUNTIF('Resultats Reals'!$E$2:$E$33,G3)>0),1,0))+IF(H3='Resultats Reals'!$C$17,2,IF(OR(H3='Resultats Reals'!$C$18,COUNTIF('Resultats Reals'!$E$2:$E$33,H3)>0),1,0))+IF(I3='Resultats Reals'!$C$20,2,IF(OR(I3='Resultats Reals'!$C$21,COUNTIF('Resultats Reals'!$E$2:$E$33,I3)>0),1,0))+IF(J3='Resultats Reals'!$C$23,2,IF(OR(J3='Resultats Reals'!$C$24,COUNTIF('Resultats Reals'!$E$2:$E$33,J3)>0),1,0))+IF(K3='Resultats Reals'!$C$26,2,IF(OR(K3='Resultats Reals'!$C$27,COUNTIF('Resultats Reals'!$E$2:$E$33,K3)>0),1,0))+IF(L3='Resultats Reals'!$C$29,2,IF(OR(L3='Resultats Reals'!$C$30,COUNTIF('Resultats Reals'!$E$2:$E$33,L3)>0),1,0))+IF(M3='Resultats Reals'!$C$32,2,IF(OR(M3='Resultats Reals'!$C$33,COUNTIF('Resultats Reals'!$E$2:$E$33,M3)>0),1,0))+IF(N3='Resultats Reals'!$C$35,2,IF(OR(N3='Resultats Reals'!$C$36,COUNTIF('Resultats Reals'!$E$2:$E$33,N3)>0),1,0)) -> 22 | BV3: =IF(O3='Resultats Reals'!$C$3,2,IF(OR(O3='Resultats Reals'!$C$2,COUNTIF('Resultats Reals'!$E$2:$E$33,O3)>0),1,0))+IF(P3='Resultats Reals'!$C$6,2,IF(OR(P3='Resultats Reals'!$C$5,COUNTIF('Resultats Reals'!$E$2:$E$33,P3)>0),1,0))+IF(Q3='Resultats Reals'!$C$9,2,IF(OR(Q3='Resultats Reals'!$C$8,COUNTIF('Resultats Reals'!$E$2:$E$33,Q3)>0),1,0))+IF(R3='Resultats Reals'!$C$12,2,IF(OR(R3='Resultats Reals'!$C$11,COUNTIF('Resultats Reals'!$E$2:$E$33,R3)>0),1,0))+IF(S3='Resultats Reals'!$C$15,2,IF(OR(S3='Resultats Reals'!$C$14,COUNTIF('Resultats Reals'!$E$2:$E$33,S3)>0),1,0))+IF(T3='Resultats Reals'!$C$18,2,IF(OR(T3='Resultats Reals'!$C$17,COUNTIF('Resultats Reals'!$E$2:$E$33,T3)>0),1,0))+IF(U3='Resultats Reals'!$C$21,2,IF(OR(U3='Resultats Reals'!$C$20,COUNTIF('Resultats Reals'!$E$2:$E$33,U3)>0),1,0))+IF(V3='Resultats Reals'!$C$24,2,IF(OR(V3='Resultats Reals'!$C$23,COUNTIF('Resultats Reals'!$E$2:$E$33,V3)>0),1,0))+IF(W3='Resultats Reals'!$C$27,2,IF(OR(W3='Resultats Reals'!$C$26,COUNTIF('Resultats Reals'!$E$2:$E$33,W3)>0),1,0))+IF(X3='Resultats Reals'!$C$30,2,IF(OR(X3='Resultats Reals'!$C$29,COUNTIF('Resultats Reals'!$E$2:$E$33,X3)>0),1,0))+IF(Y3='Resultats Reals'!$C$33,2,IF(OR(Y3='Resultats Reals'!$C$32,COUNTIF('Resultats Reals'!$E$2:$E$33,Y3)>0),1,0))+IF(Z3='Resultats Reals'!$C$36,2,IF(OR(Z3='Resultats Reals'!$C$35,COUNTIF('Resultats Reals'!$E$2:$E$33,Z3)>0),1,0)) -> 16 | BW3: =IF(AA3='Resultats Reals'!$C$4,IF(COUNTIF('Resultats Reals'!$E$2:$E$33,AA3)>0,2,0.5),IF(OR(AA3='Resultats Reals'!$C$2,AA3='Resultats Reals'!$C$3,COUNTIF('Resultats Reals'!$E$2:$E$33,AA3)>0),1,0))+IF(AB3='Resultats Reals'!$C$7,IF(COUNTIF('Resultats Reals'!$E$2:$E$33,AB3)>0,2,0.5),IF(OR(AB3='Resultats Reals'!$C$5,AB3='Resultats Reals'!$C$6,COUNTIF('Resultats Reals'!$E$2:$E$33,AB3)>0),1,0))+IF(AC3='Resultats Reals'!$C$10,IF(COUNTIF('Resultats Reals'!$E$2:$E$33,AC3)>0,2,0.5),IF(OR(AC3='Resultats Reals'!$C$8,AC3='Resultats Reals'!$C$9,COUNTIF('Resultats Reals'!$E$2:$E$33,AC3)>0),1,0))+IF(AD3='Resultats Reals'!$C$13,IF(COUNTIF('Resultats Reals'!$E$2:$E$33,AD3)>0,2,0.5),IF(OR(AD3='Resultats Reals'!$C$11,AD3='Resultats Reals'!$C$12,COUNTIF('Resultats Reals'!$E$2:$E$33,AD3)>0),1,0))+IF(AE3='Resultats Reals'!$C$16,IF(COUNTIF('Resultats Reals'!$E$2:$E$33,AE3)>0,2,0.5),IF(OR(AE3='Resultats Reals'!$C$14,AE3='Resultats Reals'!$C$15,COUNTIF('Resultats Reals'!$E$2:$E$33,AE3)>0),1,0))+IF(AF3='Resultats Reals'!$C$19,IF(COUNTIF('Resultats Reals'!$E$2:$E$33,AF3)>0,2,0.5),IF(OR(AF3='Resultats Reals'!$C$17,AF3='Resultats Reals'!$C$18,COUNTIF('Resultats Reals'!$E$2:$E$33,AF3)>0),1,0))+IF(AG3='Resultats Reals'!$C$22,IF(COUNTIF('Resultats Reals'!$E$2:$E$33,AG3)>0,2,0.5),IF(OR(AG3='Resultats Reals'!$C$20,AG3='Resultats Reals'!$C$21,COUNTIF('Resultats Reals'!$E$2:$E$33,AG3)>0),1,0))+IF(AH3='Resultats Reals'!$C$25,IF(COUNTIF('Resultats Reals'!$E$2:$E$33,AH3)>0,2,0.5),IF(OR(AH3='Resultats Reals'!$C$23,AH3='Resultats Reals'!$C$24,COUNTIF('Resultats Reals'!$E$2:$E$33,AH3)>0),1,0))+IF(AI3='Resultats Reals'!$C$28,IF(COUNTIF('Resultats Reals'!$E$2:$E$33,AI3)>0,2,0.5),IF(OR(AI3='Resultats Reals'!$C$26,AI3='Resultats Reals'!$C$27,COUNTIF('Resultats Reals'!$E$2:$E$33,AI3)>0),1,0))+IF(AJ3='Resultats Reals'!$C$31,IF(COUNTIF('Resultats Reals'!$E$2:$E$33,AJ3)>0,2,0.5),IF(OR(AJ3='Resultats Reals'!$C$29,AJ3='Resultats Reals'!$C$30,COUNTIF('Resultats Reals'!$E$2:$E$33,AJ3)>0),1,0))+IF(AK3='Resultats Reals'!$C$34,IF(COUNTIF('Resultats Reals'!$E$2:$E$33,AK3)>0,2,0.5),IF(OR(AK3='Resultats Reals'!$C$32,AK3='Resultats Reals'!$C$33,COUNTIF('Resultats Reals'!$E$2:$E$33,AK3)>0),1,0))+IF(AL3='Resultats Reals'!$C$37,IF(COUNTIF('Resultats Reals'!$E$2:$E$33,AL3)>0,2,0.5),IF(OR(AL3='Resultats Reals'!$C$35,AL3='Resultats Reals'!$C$36,COUNTIF('Resultats Reals'!$E$2:$E$33,AL3)>0),1,0)) -> 12 | BX3: =IF(COUNTIF('Resultats Reals'!$F$2:$F$17,AM3)>0,1,0)+IF(COUNTIF('Resultats Reals'!$F$2:$F$17,AN3)>0,1,0)+IF(COUNTIF('Resultats Reals'!$F$2:$F$17,AO3)>0,1,0)+IF(COUNTIF('Resultats Reals'!$F$2:$F$17,AP3)>0,1,0)+IF(COUNTIF('Resultats Reals'!$F$2:$F$17,AQ3)>0,1,0)+IF(COUNTIF('Resultats Reals'!$F$2:$F$17,AR3)>0,1,0)+IF(COUNTIF('Resultats Reals'!$F$2:$F$17,AS3)>0,1,0)+IF(COUNTIF('Resultats Reals'!$F$2:$F$17,AT3)>0,1,0)+IF(COUNTIF('Resultats Reals'!$F$2:$F$17,AU3)>0,1,0)+IF(COUNTIF('Resultats Reals'!$F$2:$F$17,AV3)>0,1,0)+IF(COUNTIF('Resultats Reals'!$F$2:$F$17,AW3)>0,1,0)+IF(COUNTIF('Resultats Reals'!$F$2:$F$17,AX3)>0,1,0)+IF(COUNTIF('Resultats Reals'!$F$2:$F$17,AY3)>0,1,0)+IF(COUNTIF('Resultats Reals'!$F$2:$F$17,AZ3)>0,1,0)+IF(COUNTIF('Resultats Reals'!$F$2:$F$17,BA3)>0,1,0)+IF(COUNTIF('Resultats Reals'!$F$2:$F$17,BB3)>0,1,0) -> 11 | BY3: =IF(COUNTIF('Resultats Reals'!$G$2:$G$9,BC3)>0,1,0)+IF(COUNTIF('Resultats Reals'!$G$2:$G$9,BD3)>0,1,0)+IF(COUNTIF('Resultats Reals'!$G$2:$G$9,BE3)>0,1,0)+IF(COUNTIF('Resultats Reals'!$G$2:$G$9,BF3)>0,1,0)+IF(COUNTIF('Resultats Reals'!$G$2:$G$9,BG3)>0,1,0)+IF(COUNTIF('Resultats Reals'!$G$2:$G$9,BH3)>0,1,0)+IF(COUNTIF('Resultats Reals'!$G$2:$G$9,BI3)>0,1,0)+IF(COUNTIF('Resultats Reals'!$G$2:$G$9,BJ3)>0,1,0) -> 4 | BZ3: =IF(COUNTIF('Resultats Reals'!$H$2:$H$5,BK3)>0,1,0)+IF(COUNTIF('Resultats Reals'!$H$2:$H$5,BL3)>0,1,0)+IF(COUNTIF('Resultats Reals'!$H$2:$H$5,BM3)>0,1,0)+IF(COUNTIF('Resultats Reals'!$H$2:$H$5,BN3)>0,1,0) -> 3 | CA3: =IF(COUNTIF('Resultats Reals'!$I$2:$I$3,BO3)>0,3,0)+IF(COUNTIF('Resultats Reals'!$I$2:$I$3,BP3)>0,3,0) -> 0 | CB3: =IF(BQ3='Resultats Reals'!$J$2,5,0) -> 0 | CC3: =IF(BS3='Resultats Reals'!$K$2,5,0) -> 0 | CD3: =IFERROR(VLOOKUP(BT3,'Resultats Reals'!$N$2:$O$100,2,FALSE),0) -> 8 | CE3: =IF(BR3='Resultats Reals'!$L$2,5,0) -> 0 | CF3: =SUM(BU3:CE3) -> 76
A4: Anthony Romero | B4: Obres | C4: Mèxic | D4: Canadà | E4: Brasil | F4: Turquia | G4: Alemanya | H4: Països Baixos | I4: Bèlgica | J4: Espanya | K4: França | L4: Argentina | M4: Colòmbia | N4: Anglaterra | O4: República Txeca | P4: Suïssa | Q4: Marroc | R4: Estats Units | S4: Equador | T4: Japó | U4: Iran | V4: Uruguai | W4: Noruega | X4: Algèria | Y4: Portugal | Z4: Ghana | AA4: Sud-àfrica | AB4: Bòsnia i Hercegovina | AC4: Escòcia | AD4: Paraguai | AE4: Costa d'Ivori | AF4: Suècia | AG4: Egipte | AH4: Aràbia Saudita | AI4: Senegal | AJ4: Àustria | AK4: RD Congo | AL4: Croàcia | AM4: Alemanya | AN4: França | AO4: Suïssa | AP4: Països Baixos | AQ4: Portugal | AR4: Espanya | AS4: Turquia | AT4: Bèlgica | AU4: Brasil | AV4: Noruega | AW4: Mèxic | AX4: Anglaterra | AY4: Argentina | AZ4: Estats Units | BA4: Canadà | BB4: Colòmbia | BC4: França | BD4: Països Baixos | BE4: Espanya | BF4: Bèlgica | BG4: Brasil | BH4: Anglaterra | BI4: Argentina | BJ4: Colòmbia | BK4: França | BL4: Espanya | BM4: Anglaterra | BN4: Argentina | BO4: Espanya | BP4: Anglaterra | BQ4: Espanya | BS4: Lamine Yamal | BT4: Kylian Mbappé | BU4: =IF(C4='Resultats Reals'!$C$2,2,IF(OR(C4='Resultats Reals'!$C$3,COUNTIF('Resultats Reals'!$E$2:$E$33,C4)>0),1,0))+IF(D4='Resultats Reals'!$C$5,2,IF(OR(D4='Resultats Reals'!$C$6,COUNTIF('Resultats Reals'!$E$2:$E$33,D4)>0),1,0))+IF(E4='Resultats Reals'!$C$8,2,IF(OR(E4='Resultats Reals'!$C$9,COUNTIF('Resultats Reals'!$E$2:$E$33,E4)>0),1,0))+IF(F4='Resultats Reals'!$C$11,2,IF(OR(F4='Resultats Reals'!$C$12,COUNTIF('Resultats Reals'!$E$2:$E$33,F4)>0),1,0))+IF(G4='Resultats Reals'!$C$14,2,IF(OR(G4='Resultats Reals'!$C$15,COUNTIF('Resultats Reals'!$E$2:$E$33,G4)>0),1,0))+IF(H4='Resultats Reals'!$C$17,2,IF(OR(H4='Resultats Reals'!$C$18,COUNTIF('Resultats Reals'!$E$2:$E$33,H4)>0),1,0))+IF(I4='Resultats Reals'!$C$20,2,IF(OR(I4='Resultats Reals'!$C$21,COUNTIF('Resultats Reals'!$E$2:$E$33,I4)>0),1,0))+IF(J4='Resultats Reals'!$C$23,2,IF(OR(J4='Resultats Reals'!$C$24,COUNTIF('Resultats Reals'!$E$2:$E$33,J4)>0),1,0))+IF(K4='Resultats Reals'!$C$26,2,IF(OR(K4='Resultats Reals'!$C$27,COUNTIF('Resultats Reals'!$E$2:$E$33,K4)>0),1,0))+IF(L4='Resultats Reals'!$C$29,2,IF(OR(L4='Resultats Reals'!$C$30,COUNTIF('Resultats Reals'!$E$2:$E$33,L4)>0),1,0))+IF(M4='Resultats Reals'!$C$32,2,IF(OR(M4='Resultats Reals'!$C$33,COUNTIF('Resultats Reals'!$E$2:$E$33,M4)>0),1,0))+IF(N4='Resultats Reals'!$C$35,2,IF(OR(N4='Resultats Reals'!$C$36,COUNTIF('Resultats Reals'!$E$2:$E$33,N4)>0),1,0)) -> 21 | BV4: =IF(O4='Resultats Reals'!$C$3,2,IF(OR(O4='Resultats Reals'!$C$2,COUNTIF('Resultats Reals'!$E$2:$E$33,O4)>0),1,0))+IF(P4='Resultats Reals'!$C$6,2,IF(OR(P4='Resultats Reals'!$C$5,COUNTIF('Resultats Reals'!$E$2:$E$33,P4)>0),1,0))+IF(Q4='Resultats Reals'!$C$9,2,IF(OR(Q4='Resultats Reals'!$C$8,COUNTIF('Resultats Reals'!$E$2:$E$33,Q4)>0),1,0))+IF(R4='Resultats Reals'!$C$12,2,IF(OR(R4='Resultats Reals'!$C$11,COUNTIF('Resultats Reals'!$E$2:$E$33,R4)>0),1,0))+IF(S4='Resultats Reals'!$C$15,2,IF(OR(S4='Resultats Reals'!$C$14,COUNTIF('Resultats Reals'!$E$2:$E$33,S4)>0),1,0))+IF(T4='Resultats Reals'!$C$18,2,IF(OR(T4='Resultats Reals'!$C$17,COUNTIF('Resultats Reals'!$E$2:$E$33,T4)>0),1,0))+IF(U4='Resultats Reals'!$C$21,2,IF(OR(U4='Resultats Reals'!$C$20,COUNTIF('Resultats Reals'!$E$2:$E$33,U4)>0),1,0))+IF(V4='Resultats Reals'!$C$24,2,IF(OR(V4='Resultats Reals'!$C$23,COUNTIF('Resultats Reals'!$E$2:$E$33,V4)>0),1,0))+IF(W4='Resultats Reals'!$C$27,2,IF(OR(W4='Resultats Reals'!$C$26,COUNTIF('Resultats Reals'!$E$2:$E$33,W4)>0),1,0))+IF(X4='Resultats Reals'!$C$30,2,IF(OR(X4='Resultats Reals'!$C$29,COUNTIF('Resultats Reals'!$E$2:$E$33,X4)>0),1,0))+IF(Y4='Resultats Reals'!$C$33,2,IF(OR(Y4='Resultats Reals'!$C$32,COUNTIF('Resultats Reals'!$E$2:$E$33,Y4)>0),1,0))+IF(Z4='Resultats Reals'!$C$36,2,IF(OR(Z4='Resultats Reals'!$C$35,COUNTIF('Resultats Reals'!$E$2:$E$33,Z4)>0),1,0)) -> 13 | BW4: =IF(AA4='Resultats Reals'!$C$4,IF(COUNTIF('Resultats Reals'!$E$2:$E$33,AA4)>0,2,0.5),IF(OR(AA4='Resultats Reals'!$C$2,AA4='Resultats Reals'!$C$3,COUNTIF('Resultats Reals'!$E$2:$E$33,AA4)>0),1,0))+IF(AB4='Resultats Reals'!$C$7,IF(COUNTIF('Resultats Reals'!$E$2:$E$33,AB4)>0,2,0.5),IF(OR(AB4='Resultats Reals'!$C$5,AB4='Resultats Reals'!$C$6,COUNTIF('Resultats Reals'!$E$2:$E$33,AB4)>0),1,0))+IF(AC4='Resultats Reals'!$C$10,IF(COUNTIF('Resultats Reals'!$E$2:$E$33,AC4)>0,2,0.5),IF(OR(AC4='Resultats Reals'!$C$8,AC4='Resultats Reals'!$C$9,COUNTIF('Resultats Reals'!$E$2:$E$33,AC4)>0),1,0))+IF(AD4='Resultats Reals'!$C$13,IF(COUNTIF('Resultats Reals'!$E$2:$E$33,AD4)>0,2,0.5),IF(OR(AD4='Resultats Reals'!$C$11,AD4='Resultats Reals'!$C$12,COUNTIF('Resultats Reals'!$E$2:$E$33,AD4)>0),1,0))+IF(AE4='Resultats Reals'!$C$16,IF(COUNTIF('Resultats Reals'!$E$2:$E$33,AE4)>0,2,0.5),IF(OR(AE4='Resultats Reals'!$C$14,AE4='Resultats Reals'!$C$15,COUNTIF('Resultats Reals'!$E$2:$E$33,AE4)>0),1,0))+IF(AF4='Resultats Reals'!$C$19,IF(COUNTIF('Resultats Reals'!$E$2:$E$33,AF4)>0,2,0.5),IF(OR(AF4='Resultats Reals'!$C$17,AF4='Resultats Reals'!$C$18,COUNTIF('Resultats Reals'!$E$2:$E$33,AF4)>0),1,0))+IF(AG4='Resultats Reals'!$C$22,IF(COUNTIF('Resultats Reals'!$E$2:$E$33,AG4)>0,2,0.5),IF(OR(AG4='Resultats Reals'!$C$20,AG4='Resultats Reals'!$C$21,COUNTIF('Resultats Reals'!$E$2:$E$33,AG4)>0),1,0))+IF(AH4='Resultats Reals'!$C$25,IF(COUNTIF('Resultats Reals'!$E$2:$E$33,AH4)>0,2,0.5),IF(OR(AH4='Resultats Reals'!$C$23,AH4='Resultats Reals'!$C$24,COUNTIF('Resultats Reals'!$E$2:$E$33,AH4)>0),1,0))+IF(AI4='Resultats Reals'!$C$28,IF(COUNTIF('Resultats Reals'!$E$2:$E$33,AI4)>0,2,0.5),IF(OR(AI4='Resultats Reals'!$C$26,AI4='Resultats Reals'!$C$27,COUNTIF('Resultats Reals'!$E$2:$E$33,AI4)>0),1,0))+IF(AJ4='Resultats Reals'!$C$31,IF(COUNTIF('Resultats Reals'!$E$2:$E$33,AJ4)>0,2,0.5),IF(OR(AJ4='Resultats Reals'!$C$29,AJ4='Resultats Reals'!$C$30,COUNTIF('Resultats Reals'!$E$2:$E$33,AJ4)>0),1,0))+IF(AK4='Resultats Reals'!$C$34,IF(COUNTIF('Resultats Reals'!$E$2:$E$33,AK4)>0,2,0.5),IF(OR(AK4='Resultats Reals'!$C$32,AK4='Resultats Reals'!$C$33,COUNTIF('Resultats Reals'!$E$2:$E$33,AK4)>0),1,0))+IF(AL4='Resultats Reals'!$C$37,IF(COUNTIF('Resultats Reals'!$E$2:$E$33,AL4)>0,2,0.5),IF(OR(AL4='Resultats Reals'!$C$35,AL4='Resultats Reals'!$C$36,COUNTIF('Resultats Reals'!$E$2:$E$33,AL4)>0),1,0)) -> 15.5 | BX4: =IF(COUNTIF('Resultats Reals'!$F$2:$F$17,AM4)>0,1,0)+IF(COUNTIF('Resultats Reals'!$F$2:$F$17,AN4)>0,1,0)+IF(COUNTIF('Resultats Reals'!$F$2:$F$17,AO4)>0,1,0)+IF(COUNTIF('Resultats Reals'!$F$2:$F$17,AP4)>0,1,0)+IF(COUNTIF('Resultats Reals'!$F$2:$F$17,AQ4)>0,1,0)+IF(COUNTIF('Resultats Reals'!$F$2:$F$17,AR4)>0,1,0)+IF(COUNTIF('Resultats Reals'!$F$2:$F$17,AS4)>0,1,0)+IF(COUNTIF('Resultats Reals'!$F$2:$F$17,AT4)>0,1,0)+IF(COUNTIF('Resultats Reals'!$F$2:$F$17,AU4)>0,1,0)+IF(COUNTIF('Resultats Reals'!$F$2:$F$17,AV4)>0,1,0)+IF(COUNTIF('Resultats Reals'!$F$2:$F$17,AW4)>0,1,0)+IF(COUNTIF('Resultats Reals'!$F$2:$F$17,AX4)>0,1,0)+IF(COUNTIF('Resultats Reals'!$F$2:$F$17,AY4)>0,1,0)+IF(COUNTIF('Resultats Reals'!$F$2:$F$17,AZ4)>0,1,0)+IF(COUNTIF('Resultats Reals'!$F$2:$F$17,BA4)>0,1,0)+IF(COUNTIF('Resultats Reals'!$F$2:$F$17,BB4)>0,1,0) -> 13 | BY4: =IF(COUNTIF('Resultats Reals'!$G$2:$G$9,BC4)>0,1,0)+IF(COUNTIF('Resultats Reals'!$G$2:$G$9,BD4)>0,1,0)+IF(COUNTIF('Resultats Reals'!$G$2:$G$9,BE4)>0,1,0)+IF(COUNTIF('Resultats Reals'!$G$2:$G$9,BF4)>0,1,0)+IF(COUNTIF('Resultats Reals'!$G$2:$G$9,BG4)>0,1,0)+IF(COUNTIF('Resultats Reals'!$G$2:$G$9,BH4)>0,1,0)+IF(COUNTIF('Resultats Reals'!$G$2:$G$9,BI4)>0,1,0)+IF(COUNTIF('Resultats Reals'!$G$2:$G$9,BJ4)>0,1,0) -> 5 | BZ4: =IF(COUNTIF('Resultats Reals'!$H$2:$H$5,BK4)>0,1,0)+IF(COUNTIF('Resultats Reals'!$H$2:$H$5,BL4)>0,1,0)+IF(COUNTIF('Resultats Reals'!$H$2:$H$5,BM4)>0,1,0)+IF(COUNTIF('Resultats Reals'!$H$2:$H$5,BN4)>0,1,0) -> 4 | CA4: =IF(COUNTIF('Resultats Reals'!$I$2:$I$3,BO4)>0,3,0)+IF(COUNTIF('Resultats Reals'!$I$2:$I$3,BP4)>0,3,0) -> 0 | CB4: =IF(BQ4='Resultats Reals'!$J$2,5,0) -> 0 | CC4: =IF(BS4='Resultats Reals'!$K$2,5,0) -> 0 | CD4: =IFERROR(VLOOKUP(BT4,'Resultats Reals'!$N$2:$O$100,2,FALSE),0) -> 8 | CE4: =IF(BR4='Resultats Reals'!$L$2,5,0) -> 0 | CF4: =SUM(BU4:CE4) -> 79.5
A5: Blanca Estela Corona Ruiz | B5: Manteniment | C5: Mèxic | D5: Canadà | E5: Brasil | F5: Estats Units | G5: Alemanya | H5: Països Baixos | I5: Bèlgica | J5: Espanya | K5: França | L5: Argentina | M5: Portugal | N5: Anglaterra | O5: Corea del Sud | P5: Suïssa | Q5: Marroc | R5: Turquia | S5: Costa d'Ivori | T5: Japó | U5: Iran | V5: Uruguai | W5: Senegal | X5: Àustria | Y5: Colòmbia | Z5: Croàcia | AA5: Sud-àfrica | AB5: Qatar | AC5: Escòcia | AD5: Austràlia | AE5: Equador | AF5: Suècia | AG5: Egipte | AH5: Aràbia Saudita | AI5: Noruega | AJ5: Algèria | AK5: RD Congo | AL5: Ghana | AM5: Mèxic | AN5: Canadà | AO5: Brasil | AP5: Estats Units | AQ5: Alemanya | AR5: Països Baixos | AS5: Bèlgica | AT5: Espanya | AU5: França | AV5: Argentina | AW5: Portugal | AX5: Anglaterra | AY5: Corea del Sud | AZ5: Suïssa | BA5: Uruguai | BB5: Croàcia | BC5: Espanya | BD5: França | BE5: Argentina | BF5: Brasil | BG5: Anglaterra | BH5: Portugal | BI5: Alemanya | BJ5: Països Baixos | BK5: Espanya | BL5: França | BM5: Argentina | BN5: Brasil | BO5: Espanya | BP5: Argentina | BQ5: Espanya | BS5: Lamine Yamal | BT5: Kylian Mbappé | BU5: =IF(C5='Resultats Reals'!$C$2,2,IF(OR(C5='Resultats Reals'!$C$3,COUNTIF('Resultats Reals'!$E$2:$E$33,C5)>0),1,0))+IF(D5='Resultats Reals'!$C$5,2,IF(OR(D5='Resultats Reals'!$C$6,COUNTIF('Resultats Reals'!$E$2:$E$33,D5)>0),1,0))+IF(E5='Resultats Reals'!$C$8,2,IF(OR(E5='Resultats Reals'!$C$9,COUNTIF('Resultats Reals'!$E$2:$E$33,E5)>0),1,0))+IF(F5='Resultats Reals'!$C$11,2,IF(OR(F5='Resultats Reals'!$C$12,COUNTIF('Resultats Reals'!$E$2:$E$33,F5)>0),1,0))+IF(G5='Resultats Reals'!$C$14,2,IF(OR(G5='Resultats Reals'!$C$15,COUNTIF('Resultats Reals'!$E$2:$E$33,G5)>0),1,0))+IF(H5='Resultats Reals'!$C$17,2,IF(OR(H5='Resultats Reals'!$C$18,COUNTIF('Resultats Reals'!$E$2:$E$33,H5)>0),1,0))+IF(I5='Resultats Reals'!$C$20,2,IF(OR(I5='Resultats Reals'!$C$21,COUNTIF('Resultats Reals'!$E$2:$E$33,I5)>0),1,0))+IF(J5='Resultats Reals'!$C$23,2,IF(OR(J5='Resultats Reals'!$C$24,COUNTIF('Resultats Reals'!$E$2:$E$33,J5)>0),1,0))+IF(K5='Resultats Reals'!$C$26,2,IF(OR(K5='Resultats Reals'!$C$27,COUNTIF('Resultats Reals'!$E$2:$E$33,K5)>0),1,0))+IF(L5='Resultats Reals'!$C$29,2,IF(OR(L5='Resultats Reals'!$C$30,COUNTIF('Resultats Reals'!$E$2:$E$33,L5)>0),1,0))+IF(M5='Resultats Reals'!$C$32,2,IF(OR(M5='Resultats Reals'!$C$33,COUNTIF('Resultats Reals'!$E$2:$E$33,M5)>0),1,0))+IF(N5='Resultats Reals'!$C$35,2,IF(OR(N5='Resultats Reals'!$C$36,COUNTIF('Resultats Reals'!$E$2:$E$33,N5)>0),1,0)) -> 22 | BV5: =IF(O5='Resultats Reals'!$C$3,2,IF(OR(O5='Resultats Reals'!$C$2,COUNTIF('Resultats Reals'!$E$2:$E$33,O5)>0),1,0))+IF(P5='Resultats Reals'!$C$6,2,IF(OR(P5='Resultats Reals'!$C$5,COUNTIF('Resultats Reals'!$E$2:$E$33,P5)>0),1,0))+IF(Q5='Resultats Reals'!$C$9,2,IF(OR(Q5='Resultats Reals'!$C$8,COUNTIF('Resultats Reals'!$E$2:$E$33,Q5)>0),1,0))+IF(R5='Resultats Reals'!$C$12,2,IF(OR(R5='Resultats Reals'!$C$11,COUNTIF('Resultats Reals'!$E$2:$E$33,R5)>0),1,0))+IF(S5='Resultats Reals'!$C$15,2,IF(OR(S5='Resultats Reals'!$C$14,COUNTIF('Resultats Reals'!$E$2:$E$33,S5)>0),1,0))+IF(T5='Resultats Reals'!$C$18,2,IF(OR(T5='Resultats Reals'!$C$17,COUNTIF('Resultats Reals'!$E$2:$E$33,T5)>0),1,0))+IF(U5='Resultats Reals'!$C$21,2,IF(OR(U5='Resultats Reals'!$C$20,COUNTIF('Resultats Reals'!$E$2:$E$33,U5)>0),1,0))+IF(V5='Resultats Reals'!$C$24,2,IF(OR(V5='Resultats Reals'!$C$23,COUNTIF('Resultats Reals'!$E$2:$E$33,V5)>0),1,0))+IF(W5='Resultats Reals'!$C$27,2,IF(OR(W5='Resultats Reals'!$C$26,COUNTIF('Resultats Reals'!$E$2:$E$33,W5)>0),1,0))+IF(X5='Resultats Reals'!$C$30,2,IF(OR(X5='Resultats Reals'!$C$29,COUNTIF('Resultats Reals'!$E$2:$E$33,X5)>0),1,0))+IF(Y5='Resultats Reals'!$C$33,2,IF(OR(Y5='Resultats Reals'!$C$32,COUNTIF('Resultats Reals'!$E$2:$E$33,Y5)>0),1,0))+IF(Z5='Resultats Reals'!$C$36,2,IF(OR(Z5='Resultats Reals'!$C$35,COUNTIF('Resultats Reals'!$E$2:$E$33,Z5)>0),1,0)) -> 13 | BW5: =IF(AA5='Resultats Reals'!$C$4,IF(COUNTIF('Resultats Reals'!$E$2:$E$33,AA5)>0,2,0.5),IF(OR(AA5='Resultats Reals'!$C$2,AA5='Resultats Reals'!$C$3,COUNTIF('Resultats Reals'!$E$2:$E$33,AA5)>0),1,0))+IF(AB5='Resultats Reals'!$C$7,IF(COUNTIF('Resultats Reals'!$E$2:$E$33,AB5)>0,2,0.5),IF(OR(AB5='Resultats Reals'!$C$5,AB5='Resultats Reals'!$C$6,COUNTIF('Resultats Reals'!$E$2:$E$33,AB5)>0),1,0))+IF(AC5='Resultats Reals'!$C$10,IF(COUNTIF('Resultats Reals'!$E$2:$E$33,AC5)>0,2,0.5),IF(OR(AC5='Resultats Reals'!$C$8,AC5='Resultats Reals'!$C$9,COUNTIF('Resultats Reals'!$E$2:$E$33,AC5)>0),1,0))+IF(AD5='Resultats Reals'!$C$13,IF(COUNTIF('Resultats Reals'!$E$2:$E$33,AD5)>0,2,0.5),IF(OR(AD5='Resultats Reals'!$C$11,AD5='Resultats Reals'!$C$12,COUNTIF('Resultats Reals'!$E$2:$E$33,AD5)>0),1,0))+IF(AE5='Resultats Reals'!$C$16,IF(COUNTIF('Resultats Reals'!$E$2:$E$33,AE5)>0,2,0.5),IF(OR(AE5='Resultats Reals'!$C$14,AE5='Resultats Reals'!$C$15,COUNTIF('Resultats Reals'!$E$2:$E$33,AE5)>0),1,0))+IF(AF5='Resultats Reals'!$C$19,IF(COUNTIF('Resultats Reals'!$E$2:$E$33,AF5)>0,2,0.5),IF(OR(AF5='Resultats Reals'!$C$17,AF5='Resultats Reals'!$C$18,COUNTIF('Resultats Reals'!$E$2:$E$33,AF5)>0),1,0))+IF(AG5='Resultats Reals'!$C$22,IF(COUNTIF('Resultats Reals'!$E$2:$E$33,AG5)>0,2,0.5),IF(OR(AG5='Resultats Reals'!$C$20,AG5='Resultats Reals'!$C$21,COUNTIF('Resultats Reals'!$E$2:$E$33,AG5)>0),1,0))+IF(AH5='Resultats Reals'!$C$25,IF(COUNTIF('Resultats Reals'!$E$2:$E$33,AH5)>0,2,0.5),IF(OR(AH5='Resultats Reals'!$C$23,AH5='Resultats Reals'!$C$24,COUNTIF('Resultats Reals'!$E$2:$E$33,AH5)>0),1,0))+IF(AI5='Resultats Reals'!$C$28,IF(COUNTIF('Resultats Reals'!$E$2:$E$33,AI5)>0,2,0.5),IF(OR(AI5='Resultats Reals'!$C$26,AI5='Resultats Reals'!$C$27,COUNTIF('Resultats Reals'!$E$2:$E$33,AI5)>0),1,0))+IF(AJ5='Resultats Reals'!$C$31,IF(COUNTIF('Resultats Reals'!$E$2:$E$33,AJ5)>0,2,0.5),IF(OR(AJ5='Resultats Reals'!$C$29,AJ5='Resultats Reals'!$C$30,COUNTIF('Resultats Reals'!$E$2:$E$33,AJ5)>0),1,0))+IF(AK5='Resultats Reals'!$C$34,IF(COUNTIF('Resultats Reals'!$E$2:$E$33,AK5)>0,2,0.5),IF(OR(AK5='Resultats Reals'!$C$32,AK5='Resultats Reals'!$C$33,COUNTIF('Resultats Reals'!$E$2:$E$33,AK5)>0),1,0))+IF(AL5='Resultats Reals'!$C$37,IF(COUNTIF('Resultats Reals'!$E$2:$E$33,AL5)>0,2,0.5),IF(OR(AL5='Resultats Reals'!$C$35,AL5='Resultats Reals'!$C$36,COUNTIF('Resultats Reals'!$E$2:$E$33,AL5)>0),1,0)) -> 14.5 | BX5: =IF(COUNTIF('Resultats Reals'!$F$2:$F$17,AM5)>0,1,0)+IF(COUNTIF('Resultats Reals'!$F$2:$F$17,AN5)>0,1,0)+IF(COUNTIF('Resultats Reals'!$F$2:$F$17,AO5)>0,1,0)+IF(COUNTIF('Resultats Reals'!$F$2:$F$17,AP5)>0,1,0)+IF(COUNTIF('Resultats Reals'!$F$2:$F$17,AQ5)>0,1,0)+IF(COUNTIF('Resultats Reals'!$F$2:$F$17,AR5)>0,1,0)+IF(COUNTIF('Resultats Reals'!$F$2:$F$17,AS5)>0,1,0)+IF(COUNTIF('Resultats Reals'!$F$2:$F$17,AT5)>0,1,0)+IF(COUNTIF('Resultats Reals'!$F$2:$F$17,AU5)>0,1,0)+IF(COUNTIF('Resultats Reals'!$F$2:$F$17,AV5)>0,1,0)+IF(COUNTIF('Resultats Reals'!$F$2:$F$17,AW5)>0,1,0)+IF(COUNTIF('Resultats Reals'!$F$2:$F$17,AX5)>0,1,0)+IF(COUNTIF('Resultats Reals'!$F$2:$F$17,AY5)>0,1,0)+IF(COUNTIF('Resultats Reals'!$F$2:$F$17,AZ5)>0,1,0)+IF(COUNTIF('Resultats Reals'!$F$2:$F$17,BA5)>0,1,0)+IF(COUNTIF('Resultats Reals'!$F$2:$F$17,BB5)>0,1,0) -> 11 | BY5: =IF(COUNTIF('Resultats Reals'!$G$2:$G$9,BC5)>0,1,0)+IF(COUNTIF('Resultats Reals'!$G$2:$G$9,BD5)>0,1,0)+IF(COUNTIF('Resultats Reals'!$G$2:$G$9,BE5)>0,1,0)+IF(COUNTIF('Resultats Reals'!$G$2:$G$9,BF5)>0,1,0)+IF(COUNTIF('Resultats Reals'!$G$2:$G$9,BG5)>0,1,0)+IF(COUNTIF('Resultats Reals'!$G$2:$G$9,BH5)>0,1,0)+IF(COUNTIF('Resultats Reals'!$G$2:$G$9,BI5)>0,1,0)+IF(COUNTIF('Resultats Reals'!$G$2:$G$9,BJ5)>0,1,0) -> 4 | BZ5: =IF(COUNTIF('Resultats Reals'!$H$2:$H$5,BK5)>0,1,0)+IF(COUNTIF('Resultats Reals'!$H$2:$H$5,BL5)>0,1,0)+IF(COUNTIF('Resultats Reals'!$H$2:$H$5,BM5)>0,1,0)+IF(COUNTIF('Resultats Reals'!$H$2:$H$5,BN5)>0,1,0) -> 3 | CA5: =IF(COUNTIF('Resultats Reals'!$I$2:$I$3,BO5)>0,3,0)+IF(COUNTIF('Resultats Reals'!$I$2:$I$3,BP5)>0,3,0) -> 0 | CB5: =IF(BQ5='Resultats Reals'!$J$2,5,0) -> 0 | CC5: =IF(BS5='Resultats Reals'!$K$2,5,0) -> 0 | CD5: =IFERROR(VLOOKUP(BT5,'Resultats Reals'!$N$2:$O$100,2,FALSE),0) -> 8 | CE5: =IF(BR5='Resultats Reals'!$L$2,5,0) -> 0 | CF5: =SUM(BU5:CE5) -> 75.5
A6: David Dominguez | B6: Obres | C6: Mèxic | D6: Canadà | E6: Brasil | F6: Turquia | G6: Alemanya | H6: Països Baixos | I6: Bèlgica | J6: Espanya | K6: França | L6: Argentina | M6: Portugal | N6: Anglaterra | O6: República Txeca | P6: Bòsnia i Hercegovina | Q6: Marroc | R6: Estats Units | S6: Costa d'Ivori | T6: Japó | U6: Egipte | V6: Uruguai | W6: Noruega | X6: Àustria | Y6: Colòmbia | Z6: Croàcia | AA6: Corea del Sud | AB6: Suïssa | AC6: Escòcia | AD6: Paraguai | AE6: Equador | AF6: Suècia | AG6: Iran | AH6: Aràbia Saudita | AI6: Senegal | AJ6: Algèria | AK6: RD Congo | AL6: Ghana | AM6: Alemanya | AN6: França | AO6: República Txeca | AP6: Països Baixos | AQ6: Croàcia | AR6: Espanya | AS6: Suïssa | AT6: Senegal | AU6: Brasil | AV6: Noruega | AW6: Equador | AX6: Anglaterra | AY6: Argentina | AZ6: Egipte | BA6: Canadà | BB6: Portugal | BC6: França | BD6: Països Baixos | BE6: Espanya | BF6: Senegal | BG6: Brasil | BH6: Anglaterra | BI6: Argentina | BJ6: Portugal | BK6: França | BL6: Espanya | BM6: Brasil | BN6: Argentina | BO6: Espanya | BP6: Argentina | BQ6: Espanya | BS6: Pedri | BT6: Kylian Mbappé | BU6: =IF(C6='Resultats Reals'!$C$2,2,IF(OR(C6='Resultats Reals'!$C$3,COUNTIF('Resultats Reals'!$E$2:$E$33,C6)>0),1,0))+IF(D6='Resultats Reals'!$C$5,2,IF(OR(D6='Resultats Reals'!$C$6,COUNTIF('Resultats Reals'!$E$2:$E$33,D6)>0),1,0))+IF(E6='Resultats Reals'!$C$8,2,IF(OR(E6='Resultats Reals'!$C$9,COUNTIF('Resultats Reals'!$E$2:$E$33,E6)>0),1,0))+IF(F6='Resultats Reals'!$C$11,2,IF(OR(F6='Resultats Reals'!$C$12,COUNTIF('Resultats Reals'!$E$2:$E$33,F6)>0),1,0))+IF(G6='Resultats Reals'!$C$14,2,IF(OR(G6='Resultats Reals'!$C$15,COUNTIF('Resultats Reals'!$E$2:$E$33,G6)>0),1,0))+IF(H6='Resultats Reals'!$C$17,2,IF(OR(H6='Resultats Reals'!$C$18,COUNTIF('Resultats Reals'!$E$2:$E$33,H6)>0),1,0))+IF(I6='Resultats Reals'!$C$20,2,IF(OR(I6='Resultats Reals'!$C$21,COUNTIF('Resultats Reals'!$E$2:$E$33,I6)>0),1,0))+IF(J6='Resultats Reals'!$C$23,2,IF(OR(J6='Resultats Reals'!$C$24,COUNTIF('Resultats Reals'!$E$2:$E$33,J6)>0),1,0))+IF(K6='Resultats Reals'!$C$26,2,IF(OR(K6='Resultats Reals'!$C$27,COUNTIF('Resultats Reals'!$E$2:$E$33,K6)>0),1,0))+IF(L6='Resultats Reals'!$C$29,2,IF(OR(L6='Resultats Reals'!$C$30,COUNTIF('Resultats Reals'!$E$2:$E$33,L6)>0),1,0))+IF(M6='Resultats Reals'!$C$32,2,IF(OR(M6='Resultats Reals'!$C$33,COUNTIF('Resultats Reals'!$E$2:$E$33,M6)>0),1,0))+IF(N6='Resultats Reals'!$C$35,2,IF(OR(N6='Resultats Reals'!$C$36,COUNTIF('Resultats Reals'!$E$2:$E$33,N6)>0),1,0)) -> 20 | BV6: =IF(O6='Resultats Reals'!$C$3,2,IF(OR(O6='Resultats Reals'!$C$2,COUNTIF('Resultats Reals'!$E$2:$E$33,O6)>0),1,0))+IF(P6='Resultats Reals'!$C$6,2,IF(OR(P6='Resultats Reals'!$C$5,COUNTIF('Resultats Reals'!$E$2:$E$33,P6)>0),1,0))+IF(Q6='Resultats Reals'!$C$9,2,IF(OR(Q6='Resultats Reals'!$C$8,COUNTIF('Resultats Reals'!$E$2:$E$33,Q6)>0),1,0))+IF(R6='Resultats Reals'!$C$12,2,IF(OR(R6='Resultats Reals'!$C$11,COUNTIF('Resultats Reals'!$E$2:$E$33,R6)>0),1,0))+IF(S6='Resultats Reals'!$C$15,2,IF(OR(S6='Resultats Reals'!$C$14,COUNTIF('Resultats Reals'!$E$2:$E$33,S6)>0),1,0))+IF(T6='Resultats Reals'!$C$18,2,IF(OR(T6='Resultats Reals'!$C$17,COUNTIF('Resultats Reals'!$E$2:$E$33,T6)>0),1,0))+IF(U6='Resultats Reals'!$C$21,2,IF(OR(U6='Resultats Reals'!$C$20,COUNTIF('Resultats Reals'!$E$2:$E$33,U6)>0),1,0))+IF(V6='Resultats Reals'!$C$24,2,IF(OR(V6='Resultats Reals'!$C$23,COUNTIF('Resultats Reals'!$E$2:$E$33,V6)>0),1,0))+IF(W6='Resultats Reals'!$C$27,2,IF(OR(W6='Resultats Reals'!$C$26,COUNTIF('Resultats Reals'!$E$2:$E$33,W6)>0),1,0))+IF(X6='Resultats Reals'!$C$30,2,IF(OR(X6='Resultats Reals'!$C$29,COUNTIF('Resultats Reals'!$E$2:$E$33,X6)>0),1,0))+IF(Y6='Resultats Reals'!$C$33,2,IF(OR(Y6='Resultats Reals'!$C$32,COUNTIF('Resultats Reals'!$E$2:$E$33,Y6)>0),1,0))+IF(Z6='Resultats Reals'!$C$36,2,IF(OR(Z6='Resultats Reals'!$C$35,COUNTIF('Resultats Reals'!$E$2:$E$33,Z6)>0),1,0)) -> 17 | BW6: =IF(AA6='Resultats Reals'!$C$4,IF(COUNTIF('Resultats Reals'!$E$2:$E$33,AA6)>0,2,0.5),IF(OR(AA6='Resultats Reals'!$C$2,AA6='Resultats Reals'!$C$3,COUNTIF('Resultats Reals'!$E$2:$E$33,AA6)>0),1,0))+IF(AB6='Resultats Reals'!$C$7,IF(COUNTIF('Resultats Reals'!$E$2:$E$33,AB6)>0,2,0.5),IF(OR(AB6='Resultats Reals'!$C$5,AB6='Resultats Reals'!$C$6,COUNTIF('Resultats Reals'!$E$2:$E$33,AB6)>0),1,0))+IF(AC6='Resultats Reals'!$C$10,IF(COUNTIF('Resultats Reals'!$E$2:$E$33,AC6)>0,2,0.5),IF(OR(AC6='Resultats Reals'!$C$8,AC6='Resultats Reals'!$C$9,COUNTIF('Resultats Reals'!$E$2:$E$33,AC6)>0),1,0))+IF(AD6='Resultats Reals'!$C$13,IF(COUNTIF('Resultats Reals'!$E$2:$E$33,AD6)>0,2,0.5),IF(OR(AD6='Resultats Reals'!$C$11,AD6='Resultats Reals'!$C$12,COUNTIF('Resultats Reals'!$E$2:$E$33,AD6)>0),1,0))+IF(AE6='Resultats Reals'!$C$16,IF(COUNTIF('Resultats Reals'!$E$2:$E$33,AE6)>0,2,0.5),IF(OR(AE6='Resultats Reals'!$C$14,AE6='Resultats Reals'!$C$15,COUNTIF('Resultats Reals'!$E$2:$E$33,AE6)>0),1,0))+IF(AF6='Resultats Reals'!$C$19,IF(COUNTIF('Resultats Reals'!$E$2:$E$33,AF6)>0,2,0.5),IF(OR(AF6='Resultats Reals'!$C$17,AF6='Resultats Reals'!$C$18,COUNTIF('Resultats Reals'!$E$2:$E$33,AF6)>0),1,0))+IF(AG6='Resultats Reals'!$C$22,IF(COUNTIF('Resultats Reals'!$E$2:$E$33,AG6)>0,2,0.5),IF(OR(AG6='Resultats Reals'!$C$20,AG6='Resultats Reals'!$C$21,COUNTIF('Resultats Reals'!$E$2:$E$33,AG6)>0),1,0))+IF(AH6='Resultats Reals'!$C$25,IF(COUNTIF('Resultats Reals'!$E$2:$E$33,AH6)>0,2,0.5),IF(OR(AH6='Resultats Reals'!$C$23,AH6='Resultats Reals'!$C$24,COUNTIF('Resultats Reals'!$E$2:$E$33,AH6)>0),1,0))+IF(AI6='Resultats Reals'!$C$28,IF(COUNTIF('Resultats Reals'!$E$2:$E$33,AI6)>0,2,0.5),IF(OR(AI6='Resultats Reals'!$C$26,AI6='Resultats Reals'!$C$27,COUNTIF('Resultats Reals'!$E$2:$E$33,AI6)>0),1,0))+IF(AJ6='Resultats Reals'!$C$31,IF(COUNTIF('Resultats Reals'!$E$2:$E$33,AJ6)>0,2,0.5),IF(OR(AJ6='Resultats Reals'!$C$29,AJ6='Resultats Reals'!$C$30,COUNTIF('Resultats Reals'!$E$2:$E$33,AJ6)>0),1,0))+IF(AK6='Resultats Reals'!$C$34,IF(COUNTIF('Resultats Reals'!$E$2:$E$33,AK6)>0,2,0.5),IF(OR(AK6='Resultats Reals'!$C$32,AK6='Resultats Reals'!$C$33,COUNTIF('Resultats Reals'!$E$2:$E$33,AK6)>0),1,0))+IF(AL6='Resultats Reals'!$C$37,IF(COUNTIF('Resultats Reals'!$E$2:$E$33,AL6)>0,2,0.5),IF(OR(AL6='Resultats Reals'!$C$35,AL6='Resultats Reals'!$C$36,COUNTIF('Resultats Reals'!$E$2:$E$33,AL6)>0),1,0)) -> 16.5 | BX6: =IF(COUNTIF('Resultats Reals'!$F$2:$F$17,AM6)>0,1,0)+IF(COUNTIF('Resultats Reals'!$F$2:$F$17,AN6)>0,1,0)+IF(COUNTIF('Resultats Reals'!$F$2:$F$17,AO6)>0,1,0)+IF(COUNTIF('Resultats Reals'!$F$2:$F$17,AP6)>0,1,0)+IF(COUNTIF('Resultats Reals'!$F$2:$F$17,AQ6)>0,1,0)+IF(COUNTIF('Resultats Reals'!$F$2:$F$17,AR6)>0,1,0)+IF(COUNTIF('Resultats Reals'!$F$2:$F$17,AS6)>0,1,0)+IF(COUNTIF('Resultats Reals'!$F$2:$F$17,AT6)>0,1,0)+IF(COUNTIF('Resultats Reals'!$F$2:$F$17,AU6)>0,1,0)+IF(COUNTIF('Resultats Reals'!$F$2:$F$17,AV6)>0,1,0)+IF(COUNTIF('Resultats Reals'!$F$2:$F$17,AW6)>0,1,0)+IF(COUNTIF('Resultats Reals'!$F$2:$F$17,AX6)>0,1,0)+IF(COUNTIF('Resultats Reals'!$F$2:$F$17,AY6)>0,1,0)+IF(COUNTIF('Resultats Reals'!$F$2:$F$17,AZ6)>0,1,0)+IF(COUNTIF('Resultats Reals'!$F$2:$F$17,BA6)>0,1,0)+IF(COUNTIF('Resultats Reals'!$F$2:$F$17,BB6)>0,1,0) -> 10 | BY6: =IF(COUNTIF('Resultats Reals'!$G$2:$G$9,BC6)>0,1,0)+IF(COUNTIF('Resultats Reals'!$G$2:$G$9,BD6)>0,1,0)+IF(COUNTIF('Resultats Reals'!$G$2:$G$9,BE6)>0,1,0)+IF(COUNTIF('Resultats Reals'!$G$2:$G$9,BF6)>0,1,0)+IF(COUNTIF('Resultats Reals'!$G$2:$G$9,BG6)>0,1,0)+IF(COUNTIF('Resultats Reals'!$G$2:$G$9,BH6)>0,1,0)+IF(COUNTIF('Resultats Reals'!$G$2:$G$9,BI6)>0,1,0)+IF(COUNTIF('Resultats Reals'!$G$2:$G$9,BJ6)>0,1,0) -> 4 | BZ6: =IF(COUNTIF('Resultats Reals'!$H$2:$H$5,BK6)>0,1,0)+IF(COUNTIF('Resultats Reals'!$H$2:$H$5,BL6)>0,1,0)+IF(COUNTIF('Resultats Reals'!$H$2:$H$5,BM6)>0,1,0)+IF(COUNTIF('Resultats Reals'!$H$2:$H$5,BN6)>0,1,0) -> 3 | CA6: =IF(COUNTIF('Resultats Reals'!$I$2:$I$3,BO6)>0,3,0)+IF(COUNTIF('Resultats Reals'!$I$2:$I$3,BP6)>0,3,0) -> 0 | CB6: =IF(BQ6='Resultats Reals'!$J$2,5,0) -> 0 | CC6: =IF(BS6='Resultats Reals'!$K$2,5,0) -> 0 | CD6: =IFERROR(VLOOKUP(BT6,'Resultats Reals'!$N$2:$O$100,2,FALSE),0) -> 8 | CE6: =IF(BR6='Resultats Reals'!$L$2,5,0) -> 0 | CF6: =SUM(BU6:CE6) -> 78.5
A7: Sonia Gallardo | B7: Obres | C7: Mèxic | D7: Suïssa | E7: Marroc | F7: Estats Units | G7: Alemanya | H7: Països Baixos | I7: Bèlgica | J7: Espanya | K7: França | L7: Argentina | M7: Colòmbia | N7: Anglaterra | O7: Corea del Sud | P7: Canadà | Q7: Brasil | R7: Turquia | S7: Equador | T7: Japó | U7: Egipte | V7: Uruguai | W7: Noruega | X7: Àustria | Y7: Portugal | Z7: Croàcia | AA7: República Txeca | AB7: Qatar | AC7: Escòcia | AD7: Paraguai | AE7: Costa d'Ivori | AF7: Suècia | AG7: Nova Zelanda | AH7: Aràbia Saudita | AI7: Senegal | AJ7: Algèria | AK7: Uzbekistan | AL7: Ghana | AM7: Mèxic | AN7: Suïssa | AO7: Marroc | AP7: Estats Units | AQ7: Alemanya | AR7: Països Baixos | AS7: Bèlgica | AT7: Espanya | AU7: França | AV7: Portugal | AW7: Colòmbia | AX7: Anglaterra | AY7: Corea del Sud | AZ7: Brasil | BA7: Japó | BB7: Uruguai | BC7: Mèxic | BD7: Marroc | BE7: Alemanya | BF7: Espanya | BG7: França | BH7: Anglaterra | BI7: Brasil | BJ7: Uruguai | BK7: Marroc | BL7: Espanya | BM7: França | BN7: Brasil | BO7: Espanya | BP7: França | BQ7: Espanya | BS7: Lamine Yamal | BT7: Kylian Mbappé | BU7: =IF(C7='Resultats Reals'!$C$2,2,IF(OR(C7='Resultats Reals'!$C$3,COUNTIF('Resultats Reals'!$E$2:$E$33,C7)>0),1,0))+IF(D7='Resultats Reals'!$C$5,2,IF(OR(D7='Resultats Reals'!$C$6,COUNTIF('Resultats Reals'!$E$2:$E$33,D7)>0),1,0))+IF(E7='Resultats Reals'!$C$8,2,IF(OR(E7='Resultats Reals'!$C$9,COUNTIF('Resultats Reals'!$E$2:$E$33,E7)>0),1,0))+IF(F7='Resultats Reals'!$C$11,2,IF(OR(F7='Resultats Reals'!$C$12,COUNTIF('Resultats Reals'!$E$2:$E$33,F7)>0),1,0))+IF(G7='Resultats Reals'!$C$14,2,IF(OR(G7='Resultats Reals'!$C$15,COUNTIF('Resultats Reals'!$E$2:$E$33,G7)>0),1,0))+IF(H7='Resultats Reals'!$C$17,2,IF(OR(H7='Resultats Reals'!$C$18,COUNTIF('Resultats Reals'!$E$2:$E$33,H7)>0),1,0))+IF(I7='Resultats Reals'!$C$20,2,IF(OR(I7='Resultats Reals'!$C$21,COUNTIF('Resultats Reals'!$E$2:$E$33,I7)>0),1,0))+IF(J7='Resultats Reals'!$C$23,2,IF(OR(J7='Resultats Reals'!$C$24,COUNTIF('Resultats Reals'!$E$2:$E$33,J7)>0),1,0))+IF(K7='Resultats Reals'!$C$26,2,IF(OR(K7='Resultats Reals'!$C$27,COUNTIF('Resultats Reals'!$E$2:$E$33,K7)>0),1,0))+IF(L7='Resultats Reals'!$C$29,2,IF(OR(L7='Resultats Reals'!$C$30,COUNTIF('Resultats Reals'!$E$2:$E$33,L7)>0),1,0))+IF(M7='Resultats Reals'!$C$32,2,IF(OR(M7='Resultats Reals'!$C$33,COUNTIF('Resultats Reals'!$E$2:$E$33,M7)>0),1,0))+IF(N7='Resultats Reals'!$C$35,2,IF(OR(N7='Resultats Reals'!$C$36,COUNTIF('Resultats Reals'!$E$2:$E$33,N7)>0),1,0)) -> 23 | BV7: =IF(O7='Resultats Reals'!$C$3,2,IF(OR(O7='Resultats Reals'!$C$2,COUNTIF('Resultats Reals'!$E$2:$E$33,O7)>0),1,0))+IF(P7='Resultats Reals'!$C$6,2,IF(OR(P7='Resultats Reals'!$C$5,COUNTIF('Resultats Reals'!$E$2:$E$33,P7)>0),1,0))+IF(Q7='Resultats Reals'!$C$9,2,IF(OR(Q7='Resultats Reals'!$C$8,COUNTIF('Resultats Reals'!$E$2:$E$33,Q7)>0),1,0))+IF(R7='Resultats Reals'!$C$12,2,IF(OR(R7='Resultats Reals'!$C$11,COUNTIF('Resultats Reals'!$E$2:$E$33,R7)>0),1,0))+IF(S7='Resultats Reals'!$C$15,2,IF(OR(S7='Resultats Reals'!$C$14,COUNTIF('Resultats Reals'!$E$2:$E$33,S7)>0),1,0))+IF(T7='Resultats Reals'!$C$18,2,IF(OR(T7='Resultats Reals'!$C$17,COUNTIF('Resultats Reals'!$E$2:$E$33,T7)>0),1,0))+IF(U7='Resultats Reals'!$C$21,2,IF(OR(U7='Resultats Reals'!$C$20,COUNTIF('Resultats Reals'!$E$2:$E$33,U7)>0),1,0))+IF(V7='Resultats Reals'!$C$24,2,IF(OR(V7='Resultats Reals'!$C$23,COUNTIF('Resultats Reals'!$E$2:$E$33,V7)>0),1,0))+IF(W7='Resultats Reals'!$C$27,2,IF(OR(W7='Resultats Reals'!$C$26,COUNTIF('Resultats Reals'!$E$2:$E$33,W7)>0),1,0))+IF(X7='Resultats Reals'!$C$30,2,IF(OR(X7='Resultats Reals'!$C$29,COUNTIF('Resultats Reals'!$E$2:$E$33,X7)>0),1,0))+IF(Y7='Resultats Reals'!$C$33,2,IF(OR(Y7='Resultats Reals'!$C$32,COUNTIF('Resultats Reals'!$E$2:$E$33,Y7)>0),1,0))+IF(Z7='Resultats Reals'!$C$36,2,IF(OR(Z7='Resultats Reals'!$C$35,COUNTIF('Resultats Reals'!$E$2:$E$33,Z7)>0),1,0)) -> 16 | BW7: =IF(AA7='Resultats Reals'!$C$4,IF(COUNTIF('Resultats Reals'!$E$2:$E$33,AA7)>0,2,0.5),IF(OR(AA7='Resultats Reals'!$C$2,AA7='Resultats Reals'!$C$3,COUNTIF('Resultats Reals'!$E$2:$E$33,AA7)>0),1,0))+IF(AB7='Resultats Reals'!$C$7,IF(COUNTIF('Resultats Reals'!$E$2:$E$33,AB7)>0,2,0.5),IF(OR(AB7='Resultats Reals'!$C$5,AB7='Resultats Reals'!$C$6,COUNTIF('Resultats Reals'!$E$2:$E$33,AB7)>0),1,0))+IF(AC7='Resultats Reals'!$C$10,IF(COUNTIF('Resultats Reals'!$E$2:$E$33,AC7)>0,2,0.5),IF(OR(AC7='Resultats Reals'!$C$8,AC7='Resultats Reals'!$C$9,COUNTIF('Resultats Reals'!$E$2:$E$33,AC7)>0),1,0))+IF(AD7='Resultats Reals'!$C$13,IF(COUNTIF('Resultats Reals'!$E$2:$E$33,AD7)>0,2,0.5),IF(OR(AD7='Resultats Reals'!$C$11,AD7='Resultats Reals'!$C$12,COUNTIF('Resultats Reals'!$E$2:$E$33,AD7)>0),1,0))+IF(AE7='Resultats Reals'!$C$16,IF(COUNTIF('Resultats Reals'!$E$2:$E$33,AE7)>0,2,0.5),IF(OR(AE7='Resultats Reals'!$C$14,AE7='Resultats Reals'!$C$15,COUNTIF('Resultats Reals'!$E$2:$E$33,AE7)>0),1,0))+IF(AF7='Resultats Reals'!$C$19,IF(COUNTIF('Resultats Reals'!$E$2:$E$33,AF7)>0,2,0.5),IF(OR(AF7='Resultats Reals'!$C$17,AF7='Resultats Reals'!$C$18,COUNTIF('Resultats Reals'!$E$2:$E$33,AF7)>0),1,0))+IF(AG7='Resultats Reals'!$C$22,IF(COUNTIF('Resultats Reals'!$E$2:$E$33,AG7)>0,2,0.5),IF(OR(AG7='Resultats Reals'!$C$20,AG7='Resultats Reals'!$C$21,COUNTIF('Resultats Reals'!$E$2:$E$33,AG7)>0),1,0))+IF(AH7='Resultats Reals'!$C$25,IF(COUNTIF('Resultats Reals'!$E$2:$E$33,AH7)>0,2,0.5),IF(OR(AH7='Resultats Reals'!$C$23,AH7='Resultats Reals'!$C$24,COUNTIF('Resultats Reals'!$E$2:$E$33,AH7)>0),1,0))+IF(AI7='Resultats Reals'!$C$28,IF(COUNTIF('Resultats Reals'!$E$2:$E$33,AI7)>0,2,0.5),IF(OR(AI7='Resultats Reals'!$C$26,AI7='Resultats Reals'!$C$27,COUNTIF('Resultats Reals'!$E$2:$E$33,AI7)>0),1,0))+IF(AJ7='Resultats Reals'!$C$31,IF(COUNTIF('Resultats Reals'!$E$2:$E$33,AJ7)>0,2,0.5),IF(OR(AJ7='Resultats Reals'!$C$29,AJ7='Resultats Reals'!$C$30,COUNTIF('Resultats Reals'!$E$2:$E$33,AJ7)>0),1,0))+IF(AK7='Resultats Reals'!$C$34,IF(COUNTIF('Resultats Reals'!$E$2:$E$33,AK7)>0,2,0.5),IF(OR(AK7='Resultats Reals'!$C$32,AK7='Resultats Reals'!$C$33,COUNTIF('Resultats Reals'!$E$2:$E$33,AK7)>0),1,0))+IF(AL7='Resultats Reals'!$C$37,IF(COUNTIF('Resultats Reals'!$E$2:$E$33,AL7)>0,2,0.5),IF(OR(AL7='Resultats Reals'!$C$35,AL7='Resultats Reals'!$C$36,COUNTIF('Resultats Reals'!$E$2:$E$33,AL7)>0),1,0)) -> 11.5 | BX7: =IF(COUNTIF('Resultats Reals'!$F$2:$F$17,AM7)>0,1,0)+IF(COUNTIF('Resultats Reals'!$F$2:$F$17,AN7)>0,1,0)+IF(COUNTIF('Resultats Reals'!$F$2:$F$17,AO7)>0,1,0)+IF(COUNTIF('Resultats Reals'!$F$2:$F$17,AP7)>0,1,0)+IF(COUNTIF('Resultats Reals'!$F$2:$F$17,AQ7)>0,1,0)+IF(COUNTIF('Resultats Reals'!$F$2:$F$17,AR7)>0,1,0)+IF(COUNTIF('Resultats Reals'!$F$2:$F$17,AS7)>0,1,0)+IF(COUNTIF('Resultats Reals'!$F$2:$F$17,AT7)>0,1,0)+IF(COUNTIF('Resultats Reals'!$F$2:$F$17,AU7)>0,1,0)+IF(COUNTIF('Resultats Reals'!$F$2:$F$17,AV7)>0,1,0)+IF(COUNTIF('Resultats Reals'!$F$2:$F$17,AW7)>0,1,0)+IF(COUNTIF('Resultats Reals'!$F$2:$F$17,AX7)>0,1,0)+IF(COUNTIF('Resultats Reals'!$F$2:$F$17,AY7)>0,1,0)+IF(COUNTIF('Resultats Reals'!$F$2:$F$17,AZ7)>0,1,0)+IF(COUNTIF('Resultats Reals'!$F$2:$F$17,BA7)>0,1,0)+IF(COUNTIF('Resultats Reals'!$F$2:$F$17,BB7)>0,1,0) -> 11 | BY7: =IF(COUNTIF('Resultats Reals'!$G$2:$G$9,BC7)>0,1,0)+IF(COUNTIF('Resultats Reals'!$G$2:$G$9,BD7)>0,1,0)+IF(COUNTIF('Resultats Reals'!$G$2:$G$9,BE7)>0,1,0)+IF(COUNTIF('Resultats Reals'!$G$2:$G$9,BF7)>0,1,0)+IF(COUNTIF('Resultats Reals'!$G$2:$G$9,BG7)>0,1,0)+IF(COUNTIF('Resultats Reals'!$G$2:$G$9,BH7)>0,1,0)+IF(COUNTIF('Resultats Reals'!$G$2:$G$9,BI7)>0,1,0)+IF(COUNTIF('Resultats Reals'!$G$2:$G$9,BJ7)>0,1,0) -> 4 | BZ7: =IF(COUNTIF('Resultats Reals'!$H$2:$H$5,BK7)>0,1,0)+IF(COUNTIF('Resultats Reals'!$H$2:$H$5,BL7)>0,1,0)+IF(COUNTIF('Resultats Reals'!$H$2:$H$5,BM7)>0,1,0)+IF(COUNTIF('Resultats Reals'!$H$2:$H$5,BN7)>0,1,0) -> 2 | CA7: =IF(COUNTIF('Resultats Reals'!$I$2:$I$3,BO7)>0,3,0)+IF(COUNTIF('Resultats Reals'!$I$2:$I$3,BP7)>0,3,0) -> 0 | CB7: =IF(BQ7='Resultats Reals'!$J$2,5,0) -> 0 | CC7: =IF(BS7='Resultats Reals'!$K$2,5,0) -> 0 | CD7: =IFERROR(VLOOKUP(BT7,'Resultats Reals'!$N$2:$O$100,2,FALSE),0) -> 8 | CE7: =IF(BR7='Resultats Reals'!$L$2,5,0) -> 0 | CF7: =SUM(BU7:CE7) -> 75.5
